Traceback (most recent call last):
  File "/Users/hiroyoshi/Library/Python/3.11/bin/keymap", line 8, in <module>
    sys.exit(main())
             ^^^^^^
  File "/Users/hiroyoshi/Library/Python/3.11/lib/python/site-packages/keymap_drawer/__main__.py", line 268, in main
    draw(args, config)
  File "/Users/hiroyoshi/Library/Python/3.11/lib/python/site-packages/keymap_drawer/__main__.py", line 56, in draw
    drawer = KeymapDrawer(
             ^^^^^^^^^^^^^
  File "/Users/hiroyoshi/Library/Python/3.11/lib/python/site-packages/keymap_drawer/draw/draw.py", line 24, in __init__
    self.keymap = KeymapData(config=config, **kwargs)
                  ^^^^^^^^^^^^^^^^^^^^^^^^^^^^^^^^^^^
  File "/Users/hiroyoshi/Library/Python/3.11/lib/python/site-packages/pydantic/main.py", line 250, in __init__
    validated_self = self.__pydantic_validator__.validate_python(data, self_instance=self)
                     ^^^^^^^^^^^^^^^^^^^^^^^^^^^^^^^^^^^^^^^^^^^^^^^^^^^^^^^^^^^^^^^^^^^^^
pydantic_core._pydantic_core.ValidationError: 1 validation error for KeymapData
  Assertion failed, Number of keys on layer "default" (43) does not match physical layout specification (94) [type=assertion_error, input_value={'config': Config(draw_co...': [24, 25], 'k': '='}]}, input_type=dict]
    For further information visit https://errors.pydantic.dev/2.12/v/assertion_error
